Workbook

Sheet Roster
A1: Leave Roster – Monthly View
A2: Pick the month in B3. Shows leave codes per day; weekends and public holidays are shaded.
A3: Month (1-12) | B3: 10 | D3: =TEXT(DATE(Setup!B4,B3,1),"mmmm yyyy") -> October 2026
A4: Day | C4: =IF(C5="","",TEXT(C5,"ddd")) -> Thu | D4: =IF(D5="","",TEXT(D5,"ddd")) -> Fri | E4: =IF(E5="","",TEXT(E5,"ddd")) -> Sat | F4: =IF(F5="","",TEXT(F5,"ddd")) -> Sun | G4: =IF(G5="","",TEXT(G5,"ddd")) -> Mon | H4: =IF(H5="","",TEXT(H5,"ddd")) -> Tue | I4: =IF(I5="","",TEXT(I5,"ddd")) -> Wed | J4: =IF(J5="","",TEXT(J5,"ddd")) -> Thu | ... AG4: =IF(AG5="","",TEXT(AG5,"ddd")) -> Sat
A5: Employee | B5: Dept | C5: =IF(1<=DAY(EOMONTH(DATE(Setup!$B$4,$B$3,1),0)),DATE(Setup!$B$4,$B$3,1),"") -> 46296 | D5: =IF(2<=DAY(EOMONTH(DATE(Setup!$B$4,$B$3,1),0)),DATE(Setup!$B$4,$B$3,2),"") -> 46297 | E5: =IF(3<=DAY(EOMONTH(DATE(Setup!$B$4,$B$3,1),0)),DATE(Setup!$B$4,$B$3,3),"") -> 46298 | F5: =IF(4<=DAY(EOMONTH(DATE(Setup!$B$4,$B$3,1),0)),DATE(Setup!$B$4,$B$3,4),"") -> 46299 | G5: =IF(5<=DAY(EOMONTH(DATE(Setup!$B$4,$B$3,1),0)),DATE(Setup!$B$4,$B$3,5),"") -> 46300 | H5: =IF(6<=DAY(EOMONTH(DATE(Setup!$B$4,$B$3,1),0)),DATE(Setup!$B$4,$B$3,6),"") -> 46301 | I5: =IF(7<=DAY(EOMONTH(DATE(Setup!$B$4,$B$3,1),0)),DATE(Setup!$B$4,$B$3,7),"") -> 46302 | J5: =IF(8<=DAY(EOMONTH(DATE(Setup!$B$4,$B$3,1),0)),DATE(Setup!$B$4,$B$3,8),"") -> 46303 | K5: =IF(9<=DAY(EOMONTH(DATE(Setup!$B$4,$B$3,1),0)),DATE(Setup!$B$4,$B$3,9),"") -> 46304 | L5: =IF(10<=DAY(EOMONTH(DATE(Setup!$B$4,$B$3,1),0)),DATE(Setup!$B$4,$B$3,10),"") -> 46305 | M5: =IF(11<=DAY(EOMONTH(DATE(Setup!$B$4,$B$3,1),0)),DATE(Setup!$B$4,$B$3,11),"") -> 46306 | N5: =IF(12<=DAY(EOMONTH(DATE(Setup!$B$4,$B$3,1),0)),DATE(Setup!$B$4,$B$3,12),"") -> 46307 | O5: =IF(13<=DAY(EOMONTH(DATE(Setup!$B$4,$B$3,1),0)),DATE(Setup!$B$4,$B$3,13),"") -> 46308 | P5: =IF(14<=DAY(EOMONTH(DATE(Setup!$B$4,$B$3,1),0)),DATE(Setup!$B$4,$B$3,14),"") -> 46309 | Q5: =IF(15<=DAY(EOMONTH(DATE(Setup!$B$4,$B$3,1),0)),DATE(Setup!$B$4,$B$3,15),"") -> 46310 | R5: =IF(16<=DAY(EOMONTH(DATE(Setup!$B$4,$B$3,1),0)),DATE(Setup!$B$4,$B$3,16),"") -> 46311 | S5: =IF(17<=DAY(EOMONTH(DATE(Setup!$B$4,$B$3,1),0)),DATE(Setup!$B$4,$B$3,17),"") -> 46312 | T5: =IF(18<=DAY(EOMONTH(DATE(Setup!$B$4,$B$3,1),0)),DATE(Setup!$B$4,$B$3,18),"") -> 46313 | U5: =IF(19<=DAY(EOMONTH(DATE(Setup!$B$4,$B$3,1),0)),DATE(Setup!$B$4,$B$3,19),"") -> 46314 | V5: =IF(20<=DAY(EOMONTH(DATE(Setup!$B$4,$B$3,1),0)),DATE(Setup!$B$4,$B$3,20),"") -> 46315 | W5: =IF(21<=DAY(EOMONTH(DATE(Setup!$B$4,$B$3,1),0)),DATE(Setup!$B$4,$B$3,21),"") -> 46316 | X5: =IF(22<=DAY(EOMONTH(DATE(Setup!$B$4,$B$3,1),0)),DATE(Setup!$B$4,$B$3,22),"") -> 46317 | Y5: =IF(23<=DAY(EOMONTH(DATE(Setup!$B$4,$B$3,1),0)),DATE(Setup!$B$4,$B$3,23),"") -> 46318 | Z5: =IF(24<=DAY(EOMONTH(DATE(Setup!$B$4,$B$3,1),0)),DATE(Setup!$B$4,$B$3,24),"") -> 46319 | AA5: =IF(25<=DAY(EOMONTH(DATE(Setup!$B$4,$B$3,1),0)),DATE(Setup!$B$4,$B$3,25),"") -> 46320 | AB5: =IF(26<=DAY(EOMONTH(DATE(Setup!$B$4,$B$3,1),0)),DATE(Setup!$B$4,$B$3,26),"") -> 46321 | AC5: =IF(27<=DAY(EOMONTH(DATE(Setup!$B$4,$B$3,1),0)),DATE(Setup!$B$4,$B$3,27),"") -> 46322 | AD5: =IF(28<=DAY(EOMONTH(DATE(Setup!$B$4,$B$3,1),0)),DATE(Setup!$B$4,$B$3,28),"") -> 46323 | AE5: =IF(29<=DAY(EOMONTH(DATE(Setup!$B$4,$B$3,1),0)),DATE(Setup!$B$4,$B$3,29),"") -> 46324 | AF5: =IF(30<=DAY(EOMONTH(DATE(Setup!$B$4,$B$3,1),0)),DATE(Setup!$B$4,$B$3,30),"") -> 46325 | AG5: =IF(31<=DAY(EOMONTH(DATE(Setup!$B$4,$B$3,1),0)),DATE(Setup!$B$4,$B$3,31),"") -> 46326
A6: =IF(Employees!B5="","",Employees!B5) -> Amina Yusuf | B6: =IF(Employees!B5="","",Employees!C5) -> Operations | C6: =IF(OR(C$5="",$A6=""),"",IF(COUNTIFS('Leave Log'!$A$5:$A$304,$A6,'Leave Log'!$C$5:$C$304,"<="&C$5,'Leave Log'!$D$5:$D$304,">="&C$5,'Leave Log'!$F$5:$F$304,"<>Rejected",'Leave Log'!$B$5:$B$304,"AL")>0,"AL",IF(COUNTIFS('Leave Log'!$A$5:$A$304,$A6,'Leave Log'!$C$5:$C$304,"<="&C$5,'Leave Log'!$D$5:$D$304,">="&C$5,'Leave Log'!$F$5:$F$304,"<>Rejected",'Leave Log'!$B$5:$B$304,"SL")>0,"SL",IF(COUNTIFS('Leave Log'!$A$5:$A$304,$A6,'Leave Log'!$C$5:$C$304,"<="&C$5,'Leave Log'!$D$5:$D$304,">="&C$5,'Leave Log'!$F$5:$F$304,"<>Rejected",'Leave Log'!$B$5:$B$304,"CL")>0,"CL",IF(COUNTIFS('Leave Log'!$A$5:$A$304,$A6,'Leave Log'!$C$5:$C$304,"<="&C$5,'Leave Log'!$D$5:$D$304,">="&C$5,'Leave Log'!$F$5:$F$304,"<>Rejected",'Leave Log'!$B$5:$B$304,"UL")>0,"UL",IF(COUNTIFS('Leave Log'!$A$5:$A$304,$A6,'Leave Log'!$C$5:$C$304,"<="&C$5,'Leave Log'!$D$5:$D$304,">="&C$5,'Leave Log'!$F$5:$F$304,"<>Rejected",'Leave Log'!$B$5:$B$304,"OT")>0,"OT","")))))) | D6: =IF(OR(D$5="",$A6=""),"",IF(COUNTIFS('Leave Log'!$A$5:$A$304,$A6,'Leave Log'!$C$5:$C$304,"<="&D$5,'Leave Log'!$D$5:$D$304,">="&D$5,'Leave Log'!$F$5:$F$304,"<>Rejected",'Leave Log'!$B$5:$B$304,"AL")>0,"AL",IF(COUNTIFS('Leave Log'!$A$5:$A$304,$A6,'Leave Log'!$C$5:$C$304,"<="&D$5,'Leave Log'!$D$5:$D$304,">="&D$5,'Leave Log'!$F$5:$F$304,"<>Rejected",'Leave Log'!$B$5:$B$304,"SL")>0,"SL",IF(COUNTIFS('Leave Log'!$A$5:$A$304,$A6,'Leave Log'!$C$5:$C$304,"<="&D$5,'Leave Log'!$D$5:$D$304,">="&D$5,'Leave Log'!$F$5:$F$304,"<>Rejected",'Leave Log'!$B$5:$B$304,"CL")>0,"CL",IF(COUNTIFS('Leave Log'!$A$5:$A$304,$A6,'Leave Log'!$C$5:$C$304,"<="&D$5,'Leave Log'!$D$5:$D$304,">="&D$5,'Leave Log'!$F$5:$F$304,"<>Rejected",'Leave Log'!$B$5:$B$304,"UL")>0,"UL",IF(COUNTIFS('Leave Log'!$A$5:$A$304,$A6,'Leave Log'!$C$5:$C$304,"<="&D$5,'Leave Log'!$D$5:$D$304,">="&D$5,'Leave Log'!$F$5:$F$304,"<>Rejected",'Leave Log'!$B$5:$B$304,"OT")>0,"OT","")))))) | E6: =IF(OR(E$5="",$A6=""),"",IF(COUNTIFS('Leave Log'!$A$5:$A$304,$A6,'Leave Log'!$C$5:$C$304,"<="&E$5,'Leave Log'!$D$5:$D$304,">="&E$5,'Leave Log'!$F$5:$F$304,"<>Rejected",'Leave Log'!$B$5:$B$304,"AL")>0,"AL",IF(COUNTIFS('Leave Log'!$A$5:$A$304,$A6,'Leave Log'!$C$5:$C$304,"<="&E$5,'Leave Log'!$D$5:$D$304,">="&E$5,'Leave Log'!$F$5:$F$304,"<>Rejected",'Leave Log'!$B$5:$B$304,"SL")>0,"SL",IF(COUNTIFS('Leave Log'!$A$5:$A$304,$A6,'Leave Log'!$C$5:$C$304,"<="&E$5,'Leave Log'!$D$5:$D$304,">="&E$5,'Leave Log'!$F$5:$F$304,"<>Rejected",'Leave Log'!$B$5:$B$304,"CL")>0,"CL",IF(COUNTIFS('Leave Log'!$A$5:$A$304,$A6,'Leave Log'!$C$5:$C$304,"<="&E$5,'Leave Log'!$D$5:$D$304,">="&E$5,'Leave Log'!$F$5:$F$304,"<>Rejected",'Leave Log'!$B$5:$B$304,"UL")>0,"UL",IF(COUNTIFS('Leave Log'!$A$5:$A$304,$A6,'Leave Log'!$C$5:$C$304,"<="&E$5,'Leave Log'!$D$5:$D$304,">="&E$5,'Leave Log'!$F$5:$F$304,"<>Rejected",'Leave Log'!$B$5:$B$304,"OT")>0,"OT","")))))) | F6: =IF(OR(F$5="",$A6=""),"",IF(COUNTIFS('Leave Log'!$A$5:$A$304,$A6,'Leave Log'!$C$5:$C$304,"<="&F$5,'Leave Log'!$D$5:$D$304,">="&F$5,'Leave Log'!$F$5:$F$304,"<>Rejected",'Leave Log'!$B$5:$B$304,"AL")>0,"AL",IF(COUNTIFS('Leave Log'!$A$5:$A$304,$A6,'Leave Log'!$C$5:$C$304,"<="&F$5,'Leave Log'!$D$5:$D$304,">="&F$5,'Leave Log'!$F$5:$F$304,"<>Rejected",'Leave Log'!$B$5:$B$304,"SL")>0,"SL",IF(COUNTIFS('Leave Log'!$A$5:$A$304,$A6,'Leave Log'!$C$5:$C$304,"<="&F$5,'Leave Log'!$D$5:$D$304,">="&F$5,'Leave Log'!$F$5:$F$304,"<>Rejected",'Leave Log'!$B$5:$B$304,"CL")>0,"CL",IF(COUNTIFS('Leave Log'!$A$5:$A$304,$A6,'Leave Log'!$C$5:$C$304,"<="&F$5,'Leave Log'!$D$5:$D$304,">="&F$5,'Leave Log'!$F$5:$F$304,"<>Rejected",'Leave Log'!$B$5:$B$304,"UL")>0,"UL",IF(COUNTIFS('Leave Log'!$A$5:$A$304,$A6,'Leave Log'!$C$5:$C$304,"<="&F$5,'Leave Log'!$D$5:$D$304,">="&F$5,'Leave Log'!$F$5:$F$304,"<>Rejected",'Leave Log'!$B$5:$B$304,"OT")>0,"OT","")))))) | G6: =IF(OR(G$5="",$A6=""),"",IF(COUNTIFS('Leave Log'!$A$5:$A$304,$A6,'Leave Log'!$C$5:$C$304,"<="&G$5,'Leave Log'!$D$5:$D$304,">="&G$5,'Leave Log'!$F$5:$F$304,"<>Rejected",'Leave Log'!$B$5:$B$304,"AL")>0,"AL",IF(COUNTIFS('Leave Log'!$A$5:$A$304,$A6,'Leave Log'!$C$5:$C$304,"<="&G$5,'Leave Log'!$D$5:$D$304,">="&G$5,'Leave Log'!$F$5:$F$304,"<>Rejected",'Leave Log'!$B$5:$B$304,"SL")>0,"SL",IF(COUNTIFS('Leave Log'!$A$5:$A$304,$A6,'Leave Log'!$C$5:$C$304,"<="&G$5,'Leave Log'!$D$5:$D$304,">="&G$5,'Leave Log'!$F$5:$F$304,"<>Rejected",'Leave Log'!$B$5:$B$304,"CL")>0,"CL",IF(COUNTIFS('Leave Log'!$A$5:$A$304,$A6,'Leave Log'!$C$5:$C$304,"<="&G$5,'Leave Log'!$D$5:$D$304,">="&G$5,'Leave Log'!$F$5:$F$304,"<>Rejected",'Leave Log'!$B$5:$B$304,"UL")>0,"UL",IF(COUNTIFS('Leave Log'!$A$5:$A$304,$A6,'Leave Log'!$C$5:$C$304,"<="&G$5,'Leave Log'!$D$5:$D$304,">="&G$5,'Leave Log'!$F$5:$F$304,"<>Rejected",'Leave Log'!$B$5:$B$304,"OT")>0,"OT","")))))) | H6: =IF(OR(H$5="",$A6=""),"",IF(COUNTIFS('Leave Log'!$A$5:$A$304,$A6,'Leave Log'!$C$5:$C$304,"<="&H$5,'Leave Log'!$D$5:$D$304,">="&H$5,'Leave Log'!$F$5:$F$304,"<>Rejected",'Leave Log'!$B$5:$B$304,"AL")>0,"AL",IF(COUNTIFS('Leave Log'!$A$5:$A$304,$A6,'Leave Log'!$C$5:$C$304,"<="&H$5,'Leave Log'!$D$5:$D$304,">="&H$5,'Leave Log'!$F$5:$F$304,"<>Rejected",'Leave Log'!$B$5:$B$304,"SL")>0,"SL",IF(COUNTIFS('Leave Log'!$A$5:$A$304,$A6,'Leave Log'!$C$5:$C$304,"<="&H$5,'Leave Log'!$D$5:$D$304,">="&H$5,'Leave Log'!$F$5:$F$304,"<>Rejected",'Leave Log'!$B$5:$B$304,"CL")>0,"CL",IF(COUNTIFS('Leave Log'!$A$5:$A$304,$A6,'Leave Log'!$C$5:$C$304,"<="&H$5,'Leave Log'!$D$5:$D$304,">="&H$5,'Leave Log'!$F$5:$F$304,"<>Rejected",'Leave Log'!$B$5:$B$304,"UL")>0,"UL",IF(COUNTIFS('Leave Log'!$A$5:$A$304,$A6,'Leave Log'!$C$5:$C$304,"<="&H$5,'Leave Log'!$D$5:$D$304,">="&H$5,'Leave Log'!$F$5:$F$304,"<>Rejected",'Leave Log'!$B$5:$B$304,"OT")>0,"OT","")))))) | I6: =IF(OR(I$5="",$A6=""),"",IF(COUNTIFS('Leave Log'!$A$5:$A$304,$A6,'Leave Log'!$C$5:$C$304,"<="&I$5,'Leave Log'!$D$5:$D$304,">="&I$5,'Leave Log'!$F$5:$F$304,"<>Rejected",'Leave Log'!$B$5:$B$304,"AL")>0,"AL",IF(COUNTIFS('Leave Log'!$A$5:$A$304,$A6,'Leave Log'!$C$5:$C$304,"<="&I$5,'Leave Log'!$D$5:$D$304,">="&I$5,'Leave Log'!$F$5:$F$304,"<>Rejected",'Leave Log'!$B$5:$B$304,"SL")>0,"SL",IF(COUNTIFS('Leave Log'!$A$5:$A$304,$A6,'Leave Log'!$C$5:$C$304,"<="&I$5,'Leave Log'!$D$5:$D$304,">="&I$5,'Leave Log'!$F$5:$F$304,"<>Rejected",'Leave Log'!$B$5:$B$304,"CL")>0,"CL",IF(COUNTIFS('Leave Log'!$A$5:$A$304,$A6,'Leave Log'!$C$5:$C$304,"<="&I$5,'Leave Log'!$D$5:$D$304,">="&I$5,'Leave Log'!$F$5:$F$304,"<>Rejected",'Leave Log'!$B$5:$B$304,"UL")>0,"UL",IF(COUNTIFS('Leave Log'!$A$5:$A$304,$A6,'Leave Log'!$C$5:$C$304,"<="&I$5,'Leave Log'!$D$5:$D$304,">="&I$5,'Leave Log'!$F$5:$F$304,"<>Rejected",'Leave Log'!$B$5:$B$304,"OT")>0,"OT","")))))) | J6: =IF(OR(J$5="",$A6=""),"",IF(COUNTIFS('Leave Log'!$A$5:$A$304,$A6,'Leave Log'!$C$5:$C$304,"<="&J$5,'Leave Log'!$D$5:$D$304,">="&J$5,'Leave Log'!$F$5:$F$304,"<>Rejected",'Leave Log'!$B$5:$B$304,"AL")>0,"AL",IF(COUNTIFS('Leave Log'!$A$5:$A$304,$A6,'Leave Log'!$C$5:$C$304,"<="&J$5,'Leave Log'!$D$5:$D$304,">="&J$5,'Leave Log'!$F$5:$F$304,"<>Rejected",'Leave Log'!$B$5:$B$304,"SL")>0,"SL",IF(COUNTIFS('Leave Log'!$A$5:$A$304,$A6,'Leave Log'!$C$5:$C$304,"<="&J$5,'Leave Log'!$D$5:$D$304,">="&J$5,'Leave Log'!$F$5:$F$304,"<>Rejected",'Leave Log'!$B$5:$B$304,"CL")>0,"CL",IF(COUNTIFS('Leave Log'!$A$5:$A$304,$A6,'Leave Log'!$C$5:$C$304,"<="&J$5,'Leave Log'!$D$5:$D$304,">="&J$5,'Leave Log'!$F$5:$F$304,"<>Rejected",'Leave Log'!$B$5:$B$304,"UL")>0,"UL",IF(COUNTIFS('Leave Log'!$A$5:$A$304,$A6,'Leave Log'!$C$5:$C$304,"<="&J$5,'Leave Log'!$D$5:$D$304,">="&J$5,'Leave Log'!$F$5:$F$304,"<>Rejected",'Leave Log'!$B$5:$B$304,"OT")>0,"OT","")))))) | ... AG6: =IF(OR(AG$5="",$A6=""),"",IF(COUNTIFS('Leave Log'!$A$5:$A$304,$A6,'Leave Log'!$C$5:$C$304,"<="&AG$5,'Leave Log'!$D$5:$D$304,">="&AG$5,'Leave Log'!$F$5:$F$304,"<>Rejected",'Leave Log'!$B$5:$B$304,"AL")>0,"AL",IF(COUNTIFS('Leave Log'!$A$5:$A$304,$A6,'Leave Log'!$C$5:$C$304,"<="&AG$5,'Leave Log'!$D$5:$D$304,">="&AG$5,'Leave Log'!$F$5:$F$304,"<>Rejected",'Leave Log'!$B$5:$B$304,"SL")>0,"SL",IF(COUNTIFS('Leave Log'!$A$5:$A$304,$A6,'Leave Log'!$C$5:$C$304,"<="&AG$5,'Leave Log'!$D$5:$D$304,">="&AG$5,'Leave Log'!$F$5:$F$304,"<>Rejected",'Leave Log'!$B$5:$B$304,"CL")>0,"CL",IF(COUNTIFS('Leave Log'!$A$5:$A$304,$A6,'Leave Log'!$C$5:$C$304,"<="&AG$5,'Leave Log'!$D$5:$D$304,">="&AG$5,'Leave Log'!$F$5:$F$304,"<>Rejected",'Leave Log'!$B$5:$B$304,"UL")>0,"UL",IF(COUNTIFS('Leave Log'!$A$5:$A$304,$A6,'Leave Log'!$C$5:$C$304,"<="&AG$5,'Leave Log'!$D$5:$D$304,">="&AG$5,'Leave Log'!$F$5:$F$304,"<>Rejected",'Leave Log'!$B$5:$B$304,"OT")>0,"OT",""))))))
A7: =IF(Employees!B6="","",Employees!B6) -> Brian Okafor | B7: =IF(Employees!B6="","",Employees!C6) -> Operations | C7: =IF(OR(C$5="",$A7=""),"",IF(COUNTIFS('Leave Log'!$A$5:$A$304,$A7,'Leave Log'!$C$5:$C$304,"<="&C$5,'Leave Log'!$D$5:$D$304,">="&C$5,'Leave Log'!$F$5:$F$304,"<>Rejected",'Leave Log'!$B$5:$B$304,"AL")>0,"AL",IF(COUNTIFS('Leave Log'!$A$5:$A$304,$A7,'Leave Log'!$C$5:$C$304,"<="&C$5,'Leave Log'!$D$5:$D$304,">="&C$5,'Leave Log'!$F$5:$F$304,"<>Rejected",'Leave Log'!$B$5:$B$304,"SL")>0,"SL",IF(COUNTIFS('Leave Log'!$A$5:$A$304,$A7,'Leave Log'!$C$5:$C$304,"<="&C$5,'Leave Log'!$D$5:$D$304,">="&C$5,'Leave Log'!$F$5:$F$304,"<>Rejected",'Leave Log'!$B$5:$B$304,"CL")>0,"CL",IF(COUNTIFS('Leave Log'!$A$5:$A$304,$A7,'Leave Log'!$C$5:$C$304,"<="&C$5,'Leave Log'!$D$5:$D$304,">="&C$5,'Leave Log'!$F$5:$F$304,"<>Rejected",'Leave Log'!$B$5:$B$304,"UL")>0,"UL",IF(COUNTIFS('Leave Log'!$A$5:$A$304,$A7,'Leave Log'!$C$5:$C$304,"<="&C$5,'Leave Log'!$D$5:$D$304,">="&C$5,'Leave Log'!$F$5:$F$304,"<>Rejected",'Leave Log'!$B$5:$B$304,"OT")>0,"OT","")))))) | D7: =IF(OR(D$5="",$A7=""),"",IF(COUNTIFS('Leave Log'!$A$5:$A$304,$A7,'Leave Log'!$C$5:$C$304,"<="&D$5,'Leave Log'!$D$5:$D$304,">="&D$5,'Leave Log'!$F$5:$F$304,"<>Rejected",'Leave Log'!$B$5:$B$304,"AL")>0,"AL",IF(COUNTIFS('Leave Log'!$A$5:$A$304,$A7,'Leave Log'!$C$5:$C$304,"<="&D$5,'Leave Log'!$D$5:$D$304,">="&D$5,'Leave Log'!$F$5:$F$304,"<>Rejected",'Leave Log'!$B$5:$B$304,"SL")>0,"SL",IF(COUNTIFS('Leave Log'!$A$5:$A$304,$A7,'Leave Log'!$C$5:$C$304,"<="&D$5,'Leave Log'!$D$5:$D$304,">="&D$5,'Leave Log'!$F$5:$F$304,"<>Rejected",'Leave Log'!$B$5:$B$304,"CL")>0,"CL",IF(COUNTIFS('Leave Log'!$A$5:$A$304,$A7,'Leave Log'!$C$5:$C$304,"<="&D$5,'Leave Log'!$D$5:$D$304,">="&D$5,'Leave Log'!$F$5:$F$304,"<>Rejected",'Leave Log'!$B$5:$B$304,"UL")>0,"UL",IF(COUNTIFS('Leave Log'!$A$5:$A$304,$A7,'Leave Log'!$C$5:$C$304,"<="&D$5,'Leave Log'!$D$5:$D$304,">="&D$5,'Leave Log'!$F$5:$F$304,"<>Rejected",'Leave Log'!$B$5:$B$304,"OT")>0,"OT","")))))) | E7: =IF(OR(E$5="",$A7=""),"",IF(COUNTIFS('Leave Log'!$A$5:$A$304,$A7,'Leave Log'!$C$5:$C$304,"<="&E$5,'Leave Log'!$D$5:$D$304,">="&E$5,'Leave Log'!$F$5:$F$304,"<>Rejected",'Leave Log'!$B$5:$B$304,"AL")>0,"AL",IF(COUNTIFS('Leave Log'!$A$5:$A$304,$A7,'Leave Log'!$C$5:$C$304,"<="&E$5,'Leave Log'!$D$5:$D$304,">="&E$5,'Leave Log'!$F$5:$F$304,"<>Rejected",'Leave Log'!$B$5:$B$304,"SL")>0,"SL",IF(COUNTIFS('Leave Log'!$A$5:$A$304,$A7,'Leave Log'!$C$5:$C$304,"<="&E$5,'Leave Log'!$D$5:$D$304,">="&E$5,'Leave Log'!$F$5:$F$304,"<>Rejected",'Leave Log'!$B$5:$B$304,"CL")>0,"CL",IF(COUNTIFS('Leave Log'!$A$5:$A$304,$A7,'Leave Log'!$C$5:$C$304,"<="&E$5,'Leave Log'!$D$5:$D$304,">="&E$5,'Leave Log'!$F$5:$F$304,"<>Rejected",'Leave Log'!$B$5:$B$304,"UL")>0,"UL",IF(COUNTIFS('Leave Log'!$A$5:$A$304,$A7,'Leave Log'!$C$5:$C$304,"<="&E$5,'Leave Log'!$D$5:$D$304,">="&E$5,'Leave Log'!$F$5:$F$304,"<>Rejected",'Leave Log'!$B$5:$B$304,"OT")>0,"OT","")))))) | F7: =IF(OR(F$5="",$A7=""),"",IF(COUNTIFS('Leave Log'!$A$5:$A$304,$A7,'Leave Log'!$C$5:$C$304,"<="&F$5,'Leave Log'!$D$5:$D$304,">="&F$5,'Leave Log'!$F$5:$F$304,"<>Rejected",'Leave Log'!$B$5:$B$304,"AL")>0,"AL",IF(COUNTIFS('Leave Log'!$A$5:$A$304,$A7,'Leave Log'!$C$5:$C$304,"<="&F$5,'Leave Log'!$D$5:$D$304,">="&F$5,'Leave Log'!$F$5:$F$304,"<>Rejected",'Leave Log'!$B$5:$B$304,"SL")>0,"SL",IF(COUNTIFS('Leave Log'!$A$5:$A$304,$A7,'Leave Log'!$C$5:$C$304,"<="&F$5,'Leave Log'!$D$5:$D$304,">="&F$5,'Leave Log'!$F$5:$F$304,"<>Rejected",'Leave Log'!$B$5:$B$304,"CL")>0,"CL",IF(COUNTIFS('Leave Log'!$A$5:$A$304,$A7,'Leave Log'!$C$5:$C$304,"<="&F$5,'Leave Log'!$D$5:$D$304,">="&F$5,'Leave Log'!$F$5:$F$304,"<>Rejected",'Leave Log'!$B$5:$B$304,"UL")>0,"UL",IF(COUNTIFS('Leave Log'!$A$5:$A$304,$A7,'Leave Log'!$C$5:$C$304,"<="&F$5,'Leave Log'!$D$5:$D$304,">="&F$5,'Leave Log'!$F$5:$F$304,"<>Rejected",'Leave Log'!$B$5:$B$304,"OT")>0,"OT","")))))) | G7: =IF(OR(G$5="",$A7=""),"",IF(COUNTIFS('Leave Log'!$A$5:$A$304,$A7,'Leave Log'!$C$5:$C$304,"<="&G$5,'Leave Log'!$D$5:$D$304,">="&G$5,'Leave Log'!$F$5:$F$304,"<>Rejected",'Leave Log'!$B$5:$B$304,"AL")>0,"AL",IF(COUNTIFS('Leave Log'!$A$5:$A$304,$A7,'Leave Log'!$C$5:$C$304,"<="&G$5,'Leave Log'!$D$5:$D$304,">="&G$5,'Leave Log'!$F$5:$F$304,"<>Rejected",'Leave Log'!$B$5:$B$304,"SL")>0,"SL",IF(COUNTIFS('Leave Log'!$A$5:$A$304,$A7,'Leave Log'!$C$5:$C$304,"<="&G$5,'Leave Log'!$D$5:$D$304,">="&G$5,'Leave Log'!$F$5:$F$304,"<>Rejected",'Leave Log'!$B$5:$B$304,"CL")>0,"CL",IF(COUNTIFS('Leave Log'!$A$5:$A$304,$A7,'Leave Log'!$C$5:$C$304,"<="&G$5,'Leave Log'!$D$5:$D$304,">="&G$5,'Leave Log'!$F$5:$F$304,"<>Rejected",'Leave Log'!$B$5:$B$304,"UL")>0,"UL",IF(COUNTIFS('Leave Log'!$A$5:$A$304,$A7,'Leave Log'!$C$5:$C$304,"<="&G$5,'Leave Log'!$D$5:$D$304,">="&G$5,'Leave Log'!$F$5:$F$304,"<>Rejected",'Leave Log'!$B$5:$B$304,"OT")>0,"OT","")))))) | H7: =IF(OR(H$5="",$A7=""),"",IF(COUNTIFS('Leave Log'!$A$5:$A$304,$A7,'Leave Log'!$C$5:$C$304,"<="&H$5,'Leave Log'!$D$5:$D$304,">="&H$5,'Leave Log'!$F$5:$F$304,"<>Rejected",'Leave Log'!$B$5:$B$304,"AL")>0,"AL",IF(COUNTIFS('Leave Log'!$A$5:$A$304,$A7,'Leave Log'!$C$5:$C$304,"<="&H$5,'Leave Log'!$D$5:$D$304,">="&H$5,'Leave Log'!$F$5:$F$304,"<>Rejected",'Leave Log'!$B$5:$B$304,"SL")>0,"SL",IF(COUNTIFS('Leave Log'!$A$5:$A$304,$A7,'Leave Log'!$C$5:$C$304,"<="&H$5,'Leave Log'!$D$5:$D$304,">="&H$5,'Leave Log'!$F$5:$F$304,"<>Rejected",'Leave Log'!$B$5:$B$304,"CL")>0,"CL",IF(COUNTIFS('Leave Log'!$A$5:$A$304,$A7,'Leave Log'!$C$5:$C$304,"<="&H$5,'Leave Log'!$D$5:$D$304,">="&H$5,'Leave Log'!$F$5:$F$304,"<>Rejected",'Leave Log'!$B$5:$B$304,"UL")>0,"UL",IF(COUNTIFS('Leave Log'!$A$5:$A$304,$A7,'Leave Log'!$C$5:$C$304,"<="&H$5,'Leave Log'!$D$5:$D$304,">="&H$5,'Leave Log'!$F$5:$F$304,"<>Rejected",'Leave Log'!$B$5:$B$304,"OT")>0,"OT","")))))) | I7: =IF(OR(I$5="",$A7=""),"",IF(COUNTIFS('Leave Log'!$A$5:$A$304,$A7,'Leave Log'!$C$5:$C$304,"<="&I$5,'Leave Log'!$D$5:$D$304,">="&I$5,'Leave Log'!$F$5:$F$304,"<>Rejected",'Leave Log'!$B$5:$B$304,"AL")>0,"AL",IF(COUNTIFS('Leave Log'!$A$5:$A$304,$A7,'Leave Log'!$C$5:$C$304,"<="&I$5,'Leave Log'!$D$5:$D$304,">="&I$5,'Leave Log'!$F$5:$F$304,"<>Rejected",'Leave Log'!$B$5:$B$304,"SL")>0,"SL",IF(COUNTIFS('Leave Log'!$A$5:$A$304,$A7,'Leave Log'!$C$5:$C$304,"<="&I$5,'Leave Log'!$D$5:$D$304,">="&I$5,'Leave Log'!$F$5:$F$304,"<>Rejected",'Leave Log'!$B$5:$B$304,"CL")>0,"CL",IF(COUNTIFS('Leave Log'!$A$5:$A$304,$A7,'Leave Log'!$C$5:$C$304,"<="&I$5,'Leave Log'!$D$5:$D$304,">="&I$5,'Leave Log'!$F$5:$F$304,"<>Rejected",'Leave Log'!$B$5:$B$304,"UL")>0,"UL",IF(COUNTIFS('Leave Log'!$A$5:$A$304,$A7,'Leave Log'!$C$5:$C$304,"<="&I$5,'Leave Log'!$D$5:$D$304,">="&I$5,'Leave Log'!$F$5:$F$304,"<>Rejected",'Leave Log'!$B$5:$B$304,"OT")>0,"OT","")))))) | J7: =IF(OR(J$5="",$A7=""),"",IF(COUNTIFS('Leave Log'!$A$5:$A$304,$A7,'Leave Log'!$C$5:$C$304,"<="&J$5,'Leave Log'!$D$5:$D$304,">="&J$5,'Leave Log'!$F$5:$F$304,"<>Rejected",'Leave Log'!$B$5:$B$304,"AL")>0,"AL",IF(COUNTIFS('Leave Log'!$A$5:$A$304,$A7,'Leave Log'!$C$5:$C$304,"<="&J$5,'Leave Log'!$D$5:$D$304,">="&J$5,'Leave Log'!$F$5:$F$304,"<>Rejected",'Leave Log'!$B$5:$B$304,"SL")>0,"SL",IF(COUNTIFS('Leave Log'!$A$5:$A$304,$A7,'Leave Log'!$C$5:$C$304,"<="&J$5,'Leave Log'!$D$5:$D$304,">="&J$5,'Leave Log'!$F$5:$F$304,"<>Rejected",'Leave Log'!$B$5:$B$304,"CL")>0,"CL",IF(COUNTIFS('Leave Log'!$A$5:$A$304,$A7,'Leave Log'!$C$5:$C$304,"<="&J$5,'Leave Log'!$D$5:$D$304,">="&J$5,'Leave Log'!$F$5:$F$304,"<>Rejected",'Leave Log'!$B$5:$B$304,"UL")>0,"UL",IF(COUNTIFS('Leave Log'!$A$5:$A$304,$A7,'Leave Log'!$C$5:$C$304,"<="&J$5,'Leave Log'!$D$5:$D$304,">="&J$5,'Leave Log'!$F$5:$F$304,"<>Rejected",'Leave Log'!$B$5:$B$304,"OT")>0,"OT","")))))) | ... AG7: =IF(OR(AG$5="",$A7=""),"",IF(COUNTIFS('Leave Log'!$A$5:$A$304,$A7,'Leave Log'!$C$5:$C$304,"<="&AG$5,'Leave Log'!$D$5:$D$304,">="&AG$5,'Leave Log'!$F$5:$F$304,"<>Rejected",'Leave Log'!$B$5:$B$304,"AL")>0,"AL",IF(COUNTIFS('Leave Log'!$A$5:$A$304,$A7,'Leave Log'!$C$5:$C$304,"<="&AG$5,'Leave Log'!$D$5:$D$304,">="&AG$5,'Leave Log'!$F$5:$F$304,"<>Rejected",'Leave Log'!$B$5:$B$304,"SL")>0,"SL",IF(COUNTIFS('Leave Log'!$A$5:$A$304,$A7,'Leave Log'!$C$5:$C$304,"<="&AG$5,'Leave Log'!$D$5:$D$304,">="&AG$5,'Leave Log'!$F$5:$F$304,"<>Rejected",'Leave Log'!$B$5:$B$304,"CL")>0,"CL",IF(COUNTIFS('Leave Log'!$A$5:$A$304,$A7,'Leave Log'!$C$5:$C$304,"<="&AG$5,'Leave Log'!$D$5:$D$304,">="&AG$5,'Leave Log'!$F$5:$F$304,"<>Rejected",'Leave Log'!$B$5:$B$304,"UL")>0,"UL",IF(COUNTIFS('Leave Log'!$A$5:$A$304,$A7,'Leave Log'!$C$5:$C$304,"<="&AG$5,'Leave Log'!$D$5:$D$304,">="&AG$5,'Leave Log'!$F$5:$F$304,"<>Rejected",'Leave Log'!$B$5:$B$304,"OT")>0,"OT",""))))))
A8: =IF(Employees!B7="","",Employees!B7) -> Chloe Martin | B8: =IF(Employees!B7="","",Employees!C7) -> Finance | C8: =IF(OR(C$5="",$A8=""),"",IF(COUNTIFS('Leave Log'!$A$5:$A$304,$A8,'Leave Log'!$C$5:$C$304,"<="&C$5,'Leave Log'!$D$5:$D$304,">="&C$5,'Leave Log'!$F$5:$F$304,"<>Rejected",'Leave Log'!$B$5:$B$304,"AL")>0,"AL",IF(COUNTIFS('Leave Log'!$A$5:$A$304,$A8,'Leave Log'!$C$5:$C$304,"<="&C$5,'Leave Log'!$D$5:$D$304,">="&C$5,'Leave Log'!$F$5:$F$304,"<>Rejected",'Leave Log'!$B$5:$B$304,"SL")>0,"SL",IF(COUNTIFS('Leave Log'!$A$5:$A$304,$A8,'Leave Log'!$C$5:$C$304,"<="&C$5,'Leave Log'!$D$5:$D$304,">="&C$5,'Leave Log'!$F$5:$F$304,"<>Rejected",'Leave Log'!$B$5:$B$304,"CL")>0,"CL",IF(COUNTIFS('Leave Log'!$A$5:$A$304,$A8,'Leave Log'!$C$5:$C$304,"<="&C$5,'Leave Log'!$D$5:$D$304,">="&C$5,'Leave Log'!$F$5:$F$304,"<>Rejected",'Leave Log'!$B$5:$B$304,"UL")>0,"UL",IF(COUNTIFS('Leave Log'!$A$5:$A$304,$A8,'Leave Log'!$C$5:$C$304,"<="&C$5,'Leave Log'!$D$5:$D$304,">="&C$5,'Leave Log'!$F$5:$F$304,"<>Rejected",'Leave Log'!$B$5:$B$304,"OT")>0,"OT","")))))) | D8: =IF(OR(D$5="",$A8=""),"",IF(COUNTIFS('Leave Log'!$A$5:$A$304,$A8,'Leave Log'!$C$5:$C$304,"<="&D$5,'Leave Log'!$D$5:$D$304,">="&D$5,'Leave Log'!$F$5:$F$304,"<>Rejected",'Leave Log'!$B$5:$B$304,"AL")>0,"AL",IF(COUNTIFS('Leave Log'!$A$5:$A$304,$A8,'Leave Log'!$C$5:$C$304,"<="&D$5,'Leave Log'!$D$5:$D$304,">="&D$5,'Leave Log'!$F$5:$F$304,"<>Rejected",'Leave Log'!$B$5:$B$304,"SL")>0,"SL",IF(COUNTIFS('Leave Log'!$A$5:$A$304,$A8,'Leave Log'!$C$5:$C$304,"<="&D$5,'Leave Log'!$D$5:$D$304,">="&D$5,'Leave Log'!$F$5:$F$304,"<>Rejected",'Leave Log'!$B$5:$B$304,"CL")>0,"CL",IF(COUNTIFS('Leave Log'!$A$5:$A$304,$A8,'Leave Log'!$C$5:$C$304,"<="&D$5,'Leave Log'!$D$5:$D$304,">="&D$5,'Leave Log'!$F$5:$F$304,"<>Rejected",'Leave Log'!$B$5:$B$304,"UL")>0,"UL",IF(COUNTIFS('Leave Log'!$A$5:$A$304,$A8,'Leave Log'!$C$5:$C$304,"<="&D$5,'Leave Log'!$D$5:$D$304,">="&D$5,'Leave Log'!$F$5:$F$304,"<>Rejected",'Leave Log'!$B$5:$B$304,"OT")>0,"OT","")))))) | E8: =IF(OR(E$5="",$A8=""),"",IF(COUNTIFS('Leave Log'!$A$5:$A$304,$A8,'Leave Log'!$C$5:$C$304,"<="&E$5,'Leave Log'!$D$5:$D$304,">="&E$5,'Leave Log'!$F$5:$F$304,"<>Rejected",'Leave Log'!$B$5:$B$304,"AL")>0,"AL",IF(COUNTIFS('Leave Log'!$A$5:$A$304,$A8,'Leave Log'!$C$5:$C$304,"<="&E$5,'Leave Log'!$D$5:$D$304,">="&E$5,'Leave Log'!$F$5:$F$304,"<>Rejected",'Leave Log'!$B$5:$B$304,"SL")>0,"SL",IF(COUNTIFS('Leave Log'!$A$5:$A$304,$A8,'Leave Log'!$C$5:$C$304,"<="&E$5,'Leave Log'!$D$5:$D$304,">="&E$5,'Leave Log'!$F$5:$F$304,"<>Rejected",'Leave Log'!$B$5:$B$304,"CL")>0,"CL",IF(COUNTIFS('Leave Log'!$A$5:$A$304,$A8,'Leave Log'!$C$5:$C$304,"<="&E$5,'Leave Log'!$D$5:$D$304,">="&E$5,'Leave Log'!$F$5:$F$304,"<>Rejected",'Leave Log'!$B$5:$B$304,"UL")>0,"UL",IF(COUNTIFS('Leave Log'!$A$5:$A$304,$A8,'Leave Log'!$C$5:$C$304,"<="&E$5,'Leave Log'!$D$5:$D$304,">="&E$5,'Leave Log'!$F$5:$F$304,"<>Rejected",'Leave Log'!$B$5:$B$304,"OT")>0,"OT","")))))) | F8: =IF(OR(F$5="",$A8=""),"",IF(COUNTIFS('Leave Log'!$A$5:$A$304,$A8,'Leave Log'!$C$5:$C$304,"<="&F$5,'Leave Log'!$D$5:$D$304,">="&F$5,'Leave Log'!$F$5:$F$304,"<>Rejected",'Leave Log'!$B$5:$B$304,"AL")>0,"AL",IF(COUNTIFS('Leave Log'!$A$5:$A$304,$A8,'Leave Log'!$C$5:$C$304,"<="&F$5,'Leave Log'!$D$5:$D$304,">="&F$5,'Leave Log'!$F$5:$F$304,"<>Rejected",'Leave Log'!$B$5:$B$304,"SL")>0,"SL",IF(COUNTIFS('Leave Log'!$A$5:$A$304,$A8,'Leave Log'!$C$5:$C$304,"<="&F$5,'Leave Log'!$D$5:$D$304,">="&F$5,'Leave Log'!$F$5:$F$304,"<>Rejected",'Leave Log'!$B$5:$B$304,"CL")>0,"CL",IF(COUNTIFS('Leave Log'!$A$5:$A$304,$A8,'Leave Log'!$C$5:$C$304,"<="&F$5,'Leave Log'!$D$5:$D$304,">="&F$5,'Leave Log'!$F$5:$F$304,"<>Rejected",'Leave Log'!$B$5:$B$304,"UL")>0,"UL",IF(COUNTIFS('Leave Log'!$A$5:$A$304,$A8,'Leave Log'!$C$5:$C$304,"<="&F$5,'Leave Log'!$D$5:$D$304,">="&F$5,'Leave Log'!$F$5:$F$304,"<>Rejected",'Leave Log'!$B$5:$B$304,"OT")>0,"OT","")))))) | G8: =IF(OR(G$5="",$A8=""),"",IF(COUNTIFS('Leave Log'!$A$5:$A$304,$A8,'Leave Log'!$C$5:$C$304,"<="&G$5,'Leave Log'!$D$5:$D$304,">="&G$5,'Leave Log'!$F$5:$F$304,"<>Rejected",'Leave Log'!$B$5:$B$304,"AL")>0,"AL",IF(COUNTIFS('Leave Log'!$A$5:$A$304,$A8,'Leave Log'!$C$5:$C$304,"<="&G$5,'Leave Log'!$D$5:$D$304,">="&G$5,'Leave Log'!$F$5:$F$304,"<>Rejected",'Leave Log'!$B$5:$B$304,"SL")>0,"SL",IF(COUNTIFS('Leave Log'!$A$5:$A$304,$A8,'Leave Log'!$C$5:$C$304,"<="&G$5,'Leave Log'!$D$5:$D$304,">="&G$5,'Leave Log'!$F$5:$F$304,"<>Rejected",'Leave Log'!$B$5:$B$304,"CL")>0,"CL",IF(COUNTIFS('Leave Log'!$A$5:$A$304,$A8,'Leave Log'!$C$5:$C$304,"<="&G$5,'Leave Log'!$D$5:$D$304,">="&G$5,'Leave Log'!$F$5:$F$304,"<>Rejected",'Leave Log'!$B$5:$B$304,"UL")>0,"UL",IF(COUNTIFS('Leave Log'!$A$5:$A$304,$A8,'Leave Log'!$C$5:$C$304,"<="&G$5,'Leave Log'!$D$5:$D$304,">="&G$5,'Leave Log'!$F$5:$F$304,"<>Rejected",'Leave Log'!$B$5:$B$304,"OT")>0,"OT","")))))) | H8: =IF(OR(H$5="",$A8=""),"",IF(COUNTIFS('Leave Log'!$A$5:$A$304,$A8,'Leave Log'!$C$5:$C$304,"<="&H$5,'Leave Log'!$D$5:$D$304,">="&H$5,'Leave Log'!$F$5:$F$304,"<>Rejected",'Leave Log'!$B$5:$B$304,"AL")>0,"AL",IF(COUNTIFS('Leave Log'!$A$5:$A$304,$A8,'Leave Log'!$C$5:$C$304,"<="&H$5,'Leave Log'!$D$5:$D$304,">="&H$5,'Leave Log'!$F$5:$F$304,"<>Rejected",'Leave Log'!$B$5:$B$304,"SL")>0,"SL",IF(COUNTIFS('Leave Log'!$A$5:$A$304,$A8,'Leave Log'!$C$5:$C$304,"<="&H$5,'Leave Log'!$D$5:$D$304,">="&H$5,'Leave Log'!$F$5:$F$304,"<>Rejected",'Leave Log'!$B$5:$B$304,"CL")>0,"CL",IF(COUNTIFS('Leave Log'!$A$5:$A$304,$A8,'Leave Log'!$C$5:$C$304,"<="&H$5,'Leave Log'!$D$5:$D$304,">="&H$5,'Leave Log'!$F$5:$F$304,"<>Rejected",'Leave Log'!$B$5:$B$304,"UL")>0,"UL",IF(COUNTIFS('Leave Log'!$A$5:$A$304,$A8,'Leave Log'!$C$5:$C$304,"<="&H$5,'Leave Log'!$D$5:$D$304,">="&H$5,'Leave Log'!$F$5:$F$304,"<>Rejected",'Leave Log'!$B$5:$B$304,"OT")>0,"OT","")))))) | I8: =IF(OR(I$5="",$A8=""),"",IF(COUNTIFS('Leave Log'!$A$5:$A$304,$A8,'Leave Log'!$C$5:$C$304,"<="&I$5,'Leave Log'!$D$5:$D$304,">="&I$5,'Leave Log'!$F$5:$F$304,"<>Rejected",'Leave Log'!$B$5:$B$304,"AL")>0,"AL",IF(COUNTIFS('Leave Log'!$A$5:$A$304,$A8,'Leave Log'!$C$5:$C$304,"<="&I$5,'Leave Log'!$D$5:$D$304,">="&I$5,'Leave Log'!$F$5:$F$304,"<>Rejected",'Leave Log'!$B$5:$B$304,"SL")>0,"SL",IF(COUNTIFS('Leave Log'!$A$5:$A$304,$A8,'Leave Log'!$C$5:$C$304,"<="&I$5,'Leave Log'!$D$5:$D$304,">="&I$5,'Leave Log'!$F$5:$F$304,"<>Rejected",'Leave Log'!$B$5:$B$304,"CL")>0,"CL",IF(COUNTIFS('Leave Log'!$A$5:$A$304,$A8,'Leave Log'!$C$5:$C$304,"<="&I$5,'Leave Log'!$D$5:$D$304,">="&I$5,'Leave Log'!$F$5:$F$304,"<>Rejected",'Leave Log'!$B$5:$B$304,"UL")>0,"UL",IF(COUNTIFS('Leave Log'!$A$5:$A$304,$A8,'Leave Log'!$C$5:$C$304,"<="&I$5,'Leave Log'!$D$5:$D$304,">="&I$5,'Leave Log'!$F$5:$F$304,"<>Rejected",'Leave Log'!$B$5:$B$304,"OT")>0,"OT","")))))) | J8: =IF(OR(J$5="",$A8=""),"",IF(COUNTIFS('Leave Log'!$A$5:$A$304,$A8,'Leave Log'!$C$5:$C$304,"<="&J$5,'Leave Log'!$D$5:$D$304,">="&J$5,'Leave Log'!$F$5:$F$304,"<>Rejected",'Leave Log'!$B$5:$B$304,"AL")>0,"AL",IF(COUNTIFS('Leave Log'!$A$5:$A$304,$A8,'Leave Log'!$C$5:$C$304,"<="&J$5,'Leave Log'!$D$5:$D$304,">="&J$5,'Leave Log'!$F$5:$F$304,"<>Rejected",'Leave Log'!$B$5:$B$304,"SL")>0,"SL",IF(COUNTIFS('Leave Log'!$A$5:$A$304,$A8,'Leave Log'!$C$5:$C$304,"<="&J$5,'Leave Log'!$D$5:$D$304,">="&J$5,'Leave Log'!$F$5:$F$304,"<>Rejected",'Leave Log'!$B$5:$B$304,"CL")>0,"CL",IF(COUNTIFS('Leave Log'!$A$5:$A$304,$A8,'Leave Log'!$C$5:$C$304,"<="&J$5,'Leave Log'!$D$5:$D$304,">="&J$5,'Leave Log'!$F$5:$F$304,"<>Rejected",'Leave Log'!$B$5:$B$304,"UL")>0,"UL",IF(COUNTIFS('Leave Log'!$A$5:$A$304,$A8,'Leave Log'!$C$5:$C$304,"<="&J$5,'Leave Log'!$D$5:$D$304,">="&J$5,'Leave Log'!$F$5:$F$304,"<>Rejected",'Leave Log'!$B$5:$B$304,"OT")>0,"OT","")))))) | ... AG8: =IF(OR(AG$5="",$A8=""),"",IF(COUNTIFS('Leave Log'!$A$5:$A$304,$A8,'Leave Log'!$C$5:$C$304,"<="&AG$5,'Leave Log'!$D$5:$D$304,">="&AG$5,'Leave Log'!$F$5:$F$304,"<>Rejected",'Leave Log'!$B$5:$B$304,"AL")>0,"AL",IF(COUNTIFS('Leave Log'!$A$5:$A$304,$A8,'Leave Log'!$C$5:$C$304,"<="&AG$5,'Leave Log'!$D$5:$D$304,">="&AG$5,'Leave Log'!$F$5:$F$304,"<>Rejected",'Leave Log'!$B$5:$B$304,"SL")>0,"SL",IF(COUNTIFS('Leave Log'!$A$5:$A$304,$A8,'Leave Log'!$C$5:$C$304,"<="&AG$5,'Leave Log'!$D$5:$D$304,">="&AG$5,'Leave Log'!$F$5:$F$304,"<>Rejected",'Leave Log'!$B$5:$B$304,"CL")>0,"CL",IF(COUNTIFS('Leave Log'!$A$5:$A$304,$A8,'Leave Log'!$C$5:$C$304,"<="&AG$5,'Leave Log'!$D$5:$D$304,">="&AG$5,'Leave Log'!$F$5:$F$304,"<>Rejected",'Leave Log'!$B$5:$B$304,"UL")>0,"UL",IF(COUNTIFS('Leave Log'!$A$5:$A$304,$A8,'Leave Log'!$C$5:$C$304,"<="&AG$5,'Leave Log'!$D$5:$D$304,">="&AG$5,'Leave Log'!$F$5:$F$304,"<>Rejected",'Leave Log'!$B$5:$B$304,"OT")>0,"OT","")))))) -> AL
A9: =IF(Employees!B8="","",Employees!B8) -> David Chen | B9: =IF(Employees!B8="","",Employees!C8) -> Finance | C9: =IF(OR(C$5="",$A9=""),"",IF(COUNTIFS('Leave Log'!$A$5:$A$304,$A9,'Leave Log'!$C$5:$C$304,"<="&C$5,'Leave Log'!$D$5:$D$304,">="&C$5,'Leave Log'!$F$5:$F$304,"<>Rejected",'Leave Log'!$B$5:$B$304,"AL")>0,"AL",IF(COUNTIFS('Leave Log'!$A$5:$A$304,$A9,'Leave Log'!$C$5:$C$304,"<="&C$5,'Leave Log'!$D$5:$D$304,">="&C$5,'Leave Log'!$F$5:$F$304,"<>Rejected",'Leave Log'!$B$5:$B$304,"SL")>0,"SL",IF(COUNTIFS('Leave Log'!$A$5:$A$304,$A9,'Leave Log'!$C$5:$C$304,"<="&C$5,'Leave Log'!$D$5:$D$304,">="&C$5,'Leave Log'!$F$5:$F$304,"<>Rejected",'Leave Log'!$B$5:$B$304,"CL")>0,"CL",IF(COUNTIFS('Leave Log'!$A$5:$A$304,$A9,'Leave Log'!$C$5:$C$304,"<="&C$5,'Leave Log'!$D$5:$D$304,">="&C$5,'Leave Log'!$F$5:$F$304,"<>Rejected",'Leave Log'!$B$5:$B$304,"UL")>0,"UL",IF(COUNTIFS('Leave Log'!$A$5:$A$304,$A9,'Leave Log'!$C$5:$C$304,"<="&C$5,'Leave Log'!$D$5:$D$304,">="&C$5,'Leave Log'!$F$5:$F$304,"<>Rejected",'Leave Log'!$B$5:$B$304,"OT")>0,"OT","")))))) | D9: =IF(OR(D$5="",$A9=""),"",IF(COUNTIFS('Leave Log'!$A$5:$A$304,$A9,'Leave Log'!$C$5:$C$304,"<="&D$5,'Leave Log'!$D$5:$D$304,">="&D$5,'Leave Log'!$F$5:$F$304,"<>Rejected",'Leave Log'!$B$5:$B$304,"AL")>0,"AL",IF(COUNTIFS('Leave Log'!$A$5:$A$304,$A9,'Leave Log'!$C$5:$C$304,"<="&D$5,'Leave Log'!$D$5:$D$304,">="&D$5,'Leave Log'!$F$5:$F$304,"<>Rejected",'Leave Log'!$B$5:$B$304,"SL")>0,"SL",IF(COUNTIFS('Leave Log'!$A$5:$A$304,$A9,'Leave Log'!$C$5:$C$304,"<="&D$5,'Leave Log'!$D$5:$D$304,">="&D$5,'Leave Log'!$F$5:$F$304,"<>Rejected",'Leave Log'!$B$5:$B$304,"CL")>0,"CL",IF(COUNTIFS('Leave Log'!$A$5:$A$304,$A9,'Leave Log'!$C$5:$C$304,"<="&D$5,'Leave Log'!$D$5:$D$304,">="&D$5,'Leave Log'!$F$5:$F$304,"<>Rejected",'Leave Log'!$B$5:$B$304,"UL")>0,"UL",IF(COUNTIFS('Leave Log'!$A$5:$A$304,$A9,'Leave Log'!$C$5:$C$304,"<="&D$5,'Leave Log'!$D$5:$D$304,">="&D$5,'Leave Log'!$F$5:$F$304,"<>Rejected",'Leave Log'!$B$5:$B$304,"OT")>0,"OT","")))))) | E9: =IF(OR(E$5="",$A9=""),"",IF(COUNTIFS('Leave Log'!$A$5:$A$304,$A9,'Leave Log'!$C$5:$C$304,"<="&E$5,'Leave Log'!$D$5:$D$304,">="&E$5,'Leave Log'!$F$5:$F$304,"<>Rejected",'Leave Log'!$B$5:$B$304,"AL")>0,"AL",IF(COUNTIFS('Leave Log'!$A$5:$A$304,$A9,'Leave Log'!$C$5:$C$304,"<="&E$5,'Leave Log'!$D$5:$D$304,">="&E$5,'Leave Log'!$F$5:$F$304,"<>Rejected",'Leave Log'!$B$5:$B$304,"SL")>0,"SL",IF(COUNTIFS('Leave Log'!$A$5:$A$304,$A9,'Leave Log'!$C$5:$C$304,"<="&E$5,'Leave Log'!$D$5:$D$304,">="&E$5,'Leave Log'!$F$5:$F$304,"<>Rejected",'Leave Log'!$B$5:$B$304,"CL")>0,"CL",IF(COUNTIFS('Leave Log'!$A$5:$A$304,$A9,'Leave Log'!$C$5:$C$304,"<="&E$5,'Leave Log'!$D$5:$D$304,">="&E$5,'Leave Log'!$F$5:$F$304,"<>Rejected",'Leave Log'!$B$5:$B$304,"UL")>0,"UL",IF(COUNTIFS('Leave Log'!$A$5:$A$304,$A9,'Leave Log'!$C$5:$C$304,"<="&E$5,'Leave Log'!$D$5:$D$304,">="&E$5,'Leave Log'!$F$5:$F$304,"<>Rejected",'Leave Log'!$B$5:$B$304,"OT")>0,"OT","")))))) | F9: =IF(OR(F$5="",$A9=""),"",IF(COUNTIFS('Leave Log'!$A$5:$A$304,$A9,'Leave Log'!$C$5:$C$304,"<="&F$5,'Leave Log'!$D$5:$D$304,">="&F$5,'Leave Log'!$F$5:$F$304,"<>Rejected",'Leave Log'!$B$5:$B$304,"AL")>0,"AL",IF(COUNTIFS('Leave Log'!$A$5:$A$304,$A9,'Leave Log'!$C$5:$C$304,"<="&F$5,'Leave Log'!$D$5:$D$304,">="&F$5,'Leave Log'!$F$5:$F$304,"<>Rejected",'Leave Log'!$B$5:$B$304,"SL")>0,"SL",IF(COUNTIFS('Leave Log'!$A$5:$A$304,$A9,'Leave Log'!$C$5:$C$304,"<="&F$5,'Leave Log'!$D$5:$D$304,">="&F$5,'Leave Log'!$F$5:$F$304,"<>Rejected",'Leave Log'!$B$5:$B$304,"CL")>0,"CL",IF(COUNTIFS('Leave Log'!$A$5:$A$304,$A9,'Leave Log'!$C$5:$C$304,"<="&F$5,'Leave Log'!$D$5:$D$304,">="&F$5,'Leave Log'!$F$5:$F$304,"<>Rejected",'Leave Log'!$B$5:$B$304,"UL")>0,"UL",IF(COUNTIFS('Leave Log'!$A$5:$A$304,$A9,'Leave Log'!$C$5:$C$304,"<="&F$5,'Leave Log'!$D$5:$D$304,">="&F$5,'Leave Log'!$F$5:$F$304,"<>Rejected",'Leave Log'!$B$5:$B$304,"OT")>0,"OT","")))))) | G9: =IF(OR(G$5="",$A9=""),"",IF(COUNTIFS('Leave Log'!$A$5:$A$304,$A9,'Leave Log'!$C$5:$C$304,"<="&G$5,'Leave Log'!$D$5:$D$304,">="&G$5,'Leave Log'!$F$5:$F$304,"<>Rejected",'Leave Log'!$B$5:$B$304,"AL")>0,"AL",IF(COUNTIFS('Leave Log'!$A$5:$A$304,$A9,'Leave Log'!$C$5:$C$304,"<="&G$5,'Leave Log'!$D$5:$D$304,">="&G$5,'Leave Log'!$F$5:$F$304,"<>Rejected",'Leave Log'!$B$5:$B$304,"SL")>0,"SL",IF(COUNTIFS('Leave Log'!$A$5:$A$304,$A9,'Leave Log'!$C$5:$C$304,"<="&G$5,'Leave Log'!$D$5:$D$304,">="&G$5,'Leave Log'!$F$5:$F$304,"<>Rejected",'Leave Log'!$B$5:$B$304,"CL")>0,"CL",IF(COUNTIFS('Leave Log'!$A$5:$A$304,$A9,'Leave Log'!$C$5:$C$304,"<="&G$5,'Leave Log'!$D$5:$D$304,">="&G$5,'Leave Log'!$F$5:$F$304,"<>Rejected",'Leave Log'!$B$5:$B$304,"UL")>0,"UL",IF(COUNTIFS('Leave Log'!$A$5:$A$304,$A9,'Leave Log'!$C$5:$C$304,"<="&G$5,'Leave Log'!$D$5:$D$304,">="&G$5,'Leave Log'!$F$5:$F$304,"<>Rejected",'Leave Log'!$B$5:$B$304,"OT")>0,"OT","")))))) | H9: =IF(OR(H$5="",$A9=""),"",IF(COUNTIFS('Leave Log'!$A$5:$A$304,$A9,'Leave Log'!$C$5:$C$304,"<="&H$5,'Leave Log'!$D$5:$D$304,">="&H$5,'Leave Log'!$F$5:$F$304,"<>Rejected",'Leave Log'!$B$5:$B$304,"AL")>0,"AL",IF(COUNTIFS('Leave Log'!$A$5:$A$304,$A9,'Leave Log'!$C$5:$C$304,"<="&H$5,'Leave Log'!$D$5:$D$304,">="&H$5,'Leave Log'!$F$5:$F$304,"<>Rejected",'Leave Log'!$B$5:$B$304,"SL")>0,"SL",IF(COUNTIFS('Leave Log'!$A$5:$A$304,$A9,'Leave Log'!$C$5:$C$304,"<="&H$5,'Leave Log'!$D$5:$D$304,">="&H$5,'Leave Log'!$F$5:$F$304,"<>Rejected",'Leave Log'!$B$5:$B$304,"CL")>0,"CL",IF(COUNTIFS('Leave Log'!$A$5:$A$304,$A9,'Leave Log'!$C$5:$C$304,"<="&H$5,'Leave Log'!$D$5:$D$304,">="&H$5,'Leave Log'!$F$5:$F$304,"<>Rejected",'Leave Log'!$B$5:$B$304,"UL")>0,"UL",IF(COUNTIFS('Leave Log'!$A$5:$A$304,$A9,'Leave Log'!$C$5:$C$304,"<="&H$5,'Leave Log'!$D$5:$D$304,">="&H$5,'Leave Log'!$F$5:$F$304,"<>Rejected",'Leave Log'!$B$5:$B$304,"OT")>0,"OT","")))))) | I9: =IF(OR(I$5="",$A9=""),"",IF(COUNTIFS('Leave Log'!$A$5:$A$304,$A9,'Leave Log'!$C$5:$C$304,"<="&I$5,'Leave Log'!$D$5:$D$304,">="&I$5,'Leave Log'!$F$5:$F$304,"<>Rejected",'Leave Log'!$B$5:$B$304,"AL")>0,"AL",IF(COUNTIFS('Leave Log'!$A$5:$A$304,$A9,'Leave Log'!$C$5:$C$304,"<="&I$5,'Leave Log'!$D$5:$D$304,">="&I$5,'Leave Log'!$F$5:$F$304,"<>Rejected",'Leave Log'!$B$5:$B$304,"SL")>0,"SL",IF(COUNTIFS('Leave Log'!$A$5:$A$304,$A9,'Leave Log'!$C$5:$C$304,"<="&I$5,'Leave Log'!$D$5:$D$304,">="&I$5,'Leave Log'!$F$5:$F$304,"<>Rejected",'Leave Log'!$B$5:$B$304,"CL")>0,"CL",IF(COUNTIFS('Leave Log'!$A$5:$A$304,$A9,'Leave Log'!$C$5:$C$304,"<="&I$5,'Leave Log'!$D$5:$D$304,">="&I$5,'Leave Log'!$F$5:$F$304,"<>Rejected",'Leave Log'!$B$5:$B$304,"UL")>0,"UL",IF(COUNTIFS('Leave Log'!$A$5:$A$304,$A9,'Leave Log'!$C$5:$C$304,"<="&I$5,'Leave Log'!$D$5:$D$304,">="&I$5,'Leave Log'!$F$5:$F$304,"<>Rejected",'Leave Log'!$B$5:$B$304,"OT")>0,"OT","")))))) | J9: =IF(OR(J$5="",$A9=""),"",IF(COUNTIFS('Leave Log'!$A$5:$A$304,$A9,'Leave Log'!$C$5:$C$304,"<="&J$5,'Leave Log'!$D$5:$D$304,">="&J$5,'Leave Log'!$F$5:$F$304,"<>Rejected",'Leave Log'!$B$5:$B$304,"AL")>0,"AL",IF(COUNTIFS('Leave Log'!$A$5:$A$304,$A9,'Leave Log'!$C$5:$C$304,"<="&J$5,'Leave Log'!$D$5:$D$304,">="&J$5,'Leave Log'!$F$5:$F$304,"<>Rejected",'Leave Log'!$B$5:$B$304,"SL")>0,"SL",IF(COUNTIFS('Leave Log'!$A$5:$A$304,$A9,'Leave Log'!$C$5:$C$304,"<="&J$5,'Leave Log'!$D$5:$D$304,">="&J$5,'Leave Log'!$F$5:$F$304,"<>Rejected",'Leave Log'!$B$5:$B$304,"CL")>0,"CL",IF(COUNTIFS('Leave Log'!$A$5:$A$304,$A9,'Leave Log'!$C$5:$C$304,"<="&J$5,'Leave Log'!$D$5:$D$304,">="&J$5,'Leave Log'!$F$5:$F$304,"<>Rejected",'Leave Log'!$B$5:$B$304,"UL")>0,"UL",IF(COUNTIFS('Leave Log'!$A$5:$A$304,$A9,'Leave Log'!$C$5:$C$304,"<="&J$5,'Leave Log'!$D$5:$D$304,">="&J$5,'Leave Log'!$F$5:$F$304,"<>Rejected",'Leave Log'!$B$5:$B$304,"OT")>0,"OT","")))))) | ... AG9: =IF(OR(AG$5="",$A9=""),"",IF(COUNTIFS('Leave Log'!$A$5:$A$304,$A9,'Leave Log'!$C$5:$C$304,"<="&AG$5,'Leave Log'!$D$5:$D$304,">="&AG$5,'Leave Log'!$F$5:$F$304,"<>Rejected",'Leave Log'!$B$5:$B$304,"AL")>0,"AL",IF(COUNTIFS('Leave Log'!$A$5:$A$304,$A9,'Leave Log'!$C$5:$C$304,"<="&AG$5,'Leave Log'!$D$5:$D$304,">="&AG$5,'Leave Log'!$F$5:$F$304,"<>Rejected",'Leave Log'!$B$5:$B$304,"SL")>0,"SL",IF(COUNTIFS('Leave Log'!$A$5:$A$304,$A9,'Leave Log'!$C$5:$C$304,"<="&AG$5,'Leave Log'!$D$5:$D$304,">="&AG$5,'Leave Log'!$F$5:$F$304,"<>Rejected",'Leave Log'!$B$5:$B$304,"CL")>0,"CL",IF(COUNTIFS('Leave Log'!$A$5:$A$304,$A9,'Leave Log'!$C$5:$C$304,"<="&AG$5,'Leave Log'!$D$5:$D$304,">="&AG$5,'Leave Log'!$F$5:$F$304,"<>Rejected",'Leave Log'!$B$5:$B$304,"UL")>0,"UL",IF(COUNTIFS('Leave Log'!$A$5:$A$304,$A9,'Leave Log'!$C$5:$C$304,"<="&AG$5,'Leave Log'!$D$5:$D$304,">="&AG$5,'Leave Log'!$F$5:$F$304,"<>Rejected",'Leave Log'!$B$5:$B$304,"OT")>0,"OT",""))))))
A10: =IF(Employees!B9="","",Employees!B9) -> Esther Mensah | B10: =IF(Employees!B9="","",Employees!C9) -> HR | C10: =IF(OR(C$5="",$A10=""),"",IF(COUNTIFS('Leave Log'!$A$5:$A$304,$A10,'Leave Log'!$C$5:$C$304,"<="&C$5,'Leave Log'!$D$5:$D$304,">="&C$5,'Leave Log'!$F$5:$F$304,"<>Rejected",'Leave Log'!$B$5:$B$304,"AL")>0,"AL",IF(COUNTIFS('Leave Log'!$A$5:$A$304,$A10,'Leave Log'!$C$5:$C$304,"<="&C$5,'Leave Log'!$D$5:$D$304,">="&C$5,'Leave Log'!$F$5:$F$304,"<>Rejected",'Leave Log'!$B$5:$B$304,"SL")>0,"SL",IF(COUNTIFS('Leave Log'!$A$5:$A$304,$A10,'Leave Log'!$C$5:$C$304,"<="&C$5,'Leave Log'!$D$5:$D$304,">="&C$5,'Leave Log'!$F$5:$F$304,"<>Rejected",'Leave Log'!$B$5:$B$304,"CL")>0,"CL",IF(COUNTIFS('Leave Log'!$A$5:$A$304,$A10,'Leave Log'!$C$5:$C$304,"<="&C$5,'Leave Log'!$D$5:$D$304,">="&C$5,'Leave Log'!$F$5:$F$304,"<>Rejected",'Leave Log'!$B$5:$B$304,"UL")>0,"UL",IF(COUNTIFS('Leave Log'!$A$5:$A$304,$A10,'Leave Log'!$C$5:$C$304,"<="&C$5,'Leave Log'!$D$5:$D$304,">="&C$5,'Leave Log'!$F$5:$F$304,"<>Rejected",'Leave Log'!$B$5:$B$304,"OT")>0,"OT","")))))) | D10: =IF(OR(D$5="",$A10=""),"",IF(COUNTIFS('Leave Log'!$A$5:$A$304,$A10,'Leave Log'!$C$5:$C$304,"<="&D$5,'Leave Log'!$D$5:$D$304,">="&D$5,'Leave Log'!$F$5:$F$304,"<>Rejected",'Leave Log'!$B$5:$B$304,"AL")>0,"AL",IF(COUNTIFS('Leave Log'!$A$5:$A$304,$A10,'Leave Log'!$C$5:$C$304,"<="&D$5,'Leave Log'!$D$5:$D$304,">="&D$5,'Leave Log'!$F$5:$F$304,"<>Rejected",'Leave Log'!$B$5:$B$304,"SL")>0,"SL",IF(COUNTIFS('Leave Log'!$A$5:$A$304,$A10,'Leave Log'!$C$5:$C$304,"<="&D$5,'Leave Log'!$D$5:$D$304,">="&D$5,'Leave Log'!$F$5:$F$304,"<>Rejected",'Leave Log'!$B$5:$B$304,"CL")>0,"CL",IF(COUNTIFS('Leave Log'!$A$5:$A$304,$A10,'Leave Log'!$C$5:$C$304,"<="&D$5,'Leave Log'!$D$5:$D$304,">="&D$5,'Leave Log'!$F$5:$F$304,"<>Rejected",'Leave Log'!$B$5:$B$304,"UL")>0,"UL",IF(COUNTIFS('Leave Log'!$A$5:$A$304,$A10,'Leave Log'!$C$5:$C$304,"<="&D$5,'Leave Log'!$D$5:$D$304,">="&D$5,'Leave Log'!$F$5:$F$304,"<>Rejected",'Leave Log'!$B$5:$B$304,"OT")>0,"OT","")))))) | E10: =IF(OR(E$5="",$A10=""),"",IF(COUNTIFS('Leave Log'!$A$5:$A$304,$A10,'Leave Log'!$C$5:$C$304,"<="&E$5,'Leave Log'!$D$5:$D$304,">="&E$5,'Leave Log'!$F$5:$F$304,"<>Rejected",'Leave Log'!$B$5:$B$304,"AL")>0,"AL",IF(COUNTIFS('Leave Log'!$A$5:$A$304,$A10,'Leave Log'!$C$5:$C$304,"<="&E$5,'Leave Log'!$D$5:$D$304,">="&E$5,'Leave Log'!$F$5:$F$304,"<>Rejected",'Leave Log'!$B$5:$B$304,"SL")>0,"SL",IF(COUNTIFS('Leave Log'!$A$5:$A$304,$A10,'Leave Log'!$C$5:$C$304,"<="&E$5,'Leave Log'!$D$5:$D$304,">="&E$5,'Leave Log'!$F$5:$F$304,"<>Rejected",'Leave Log'!$B$5:$B$304,"CL")>0,"CL",IF(COUNTIFS('Leave Log'!$A$5:$A$304,$A10,'Leave Log'!$C$5:$C$304,"<="&E$5,'Leave Log'!$D$5:$D$304,">="&E$5,'Leave Log'!$F$5:$F$304,"<>Rejected",'Leave Log'!$B$5:$B$304,"UL")>0,"UL",IF(COUNTIFS('Leave Log'!$A$5:$A$304,$A10,'Leave Log'!$C$5:$C$304,"<="&E$5,'Leave Log'!$D$5:$D$304,">="&E$5,'Leave Log'!$F$5:$F$304,"<>Rejected",'Leave Log'!$B$5:$B$304,"OT")>0,"OT","")))))) | F10: =IF(OR(F$5="",$A10=""),"",IF(COUNTIFS('Leave Log'!$A$5:$A$304,$A10,'Leave Log'!$C$5:$C$304,"<="&F$5,'Leave Log'!$D$5:$D$304,">="&F$5,'Leave Log'!$F$5:$F$304,"<>Rejected",'Leave Log'!$B$5:$B$304,"AL")>0,"AL",IF(COUNTIFS('Leave Log'!$A$5:$A$304,$A10,'Leave Log'!$C$5:$C$304,"<="&F$5,'Leave Log'!$D$5:$D$304,">="&F$5,'Leave Log'!$F$5:$F$304,"<>Rejected",'Leave Log'!$B$5:$B$304,"SL")>0,"SL",IF(COUNTIFS('Leave Log'!$A$5:$A$304,$A10,'Leave Log'!$C$5:$C$304,"<="&F$5,'Leave Log'!$D$5:$D$304,">="&F$5,'Leave Log'!$F$5:$F$304,"<>Rejected",'Leave Log'!$B$5:$B$304,"CL")>0,"CL",IF(COUNTIFS('Leave Log'!$A$5:$A$304,$A10,'Leave Log'!$C$5:$C$304,"<="&F$5,'Leave Log'!$D$5:$D$304,">="&F$5,'Leave Log'!$F$5:$F$304,"<>Rejected",'Leave Log'!$B$5:$B$304,"UL")>0,"UL",IF(COUNTIFS('Leave Log'!$A$5:$A$304,$A10,'Leave Log'!$C$5:$C$304,"<="&F$5,'Leave Log'!$D$5:$D$304,">="&F$5,'Leave Log'!$F$5:$F$304,"<>Rejected",'Leave Log'!$B$5:$B$304,"OT")>0,"OT","")))))) | G10: =IF(OR(G$5="",$A10=""),"",IF(COUNTIFS('Leave Log'!$A$5:$A$304,$A10,'Leave Log'!$C$5:$C$304,"<="&G$5,'Leave Log'!$D$5:$D$304,">="&G$5,'Leave Log'!$F$5:$F$304,"<>Rejected",'Leave Log'!$B$5:$B$304,"AL")>0,"AL",IF(COUNTIFS('Leave Log'!$A$5:$A$304,$A10,'Leave Log'!$C$5:$C$304,"<="&G$5,'Leave Log'!$D$5:$D$304,">="&G$5,'Leave Log'!$F$5:$F$304,"<>Rejected",'Leave Log'!$B$5:$B$304,"SL")>0,"SL",IF(COUNTIFS('Leave Log'!$A$5:$A$304,$A10,'Leave Log'!$C$5:$C$304,"<="&G$5,'Leave Log'!$D$5:$D$304,">="&G$5,'Leave Log'!$F$5:$F$304,"<>Rejected",'Leave Log'!$B$5:$B$304,"CL")>0,"CL",IF(COUNTIFS('Leave Log'!$A$5:$A$304,$A10,'Leave Log'!$C$5:$C$304,"<="&G$5,'Leave Log'!$D$5:$D$304,">="&G$5,'Leave Log'!$F$5:$F$304,"<>Rejected",'Leave Log'!$B$5:$B$304,"UL")>0,"UL",IF(COUNTIFS('Leave Log'!$A$5:$A$304,$A10,'Leave Log'!$C$5:$C$304,"<="&G$5,'Leave Log'!$D$5:$D$304,">="&G$5,'Leave Log'!$F$5:$F$304,"<>Rejected",'Leave Log'!$B$5:$B$304,"OT")>0,"OT","")))))) | H10: =IF(OR(H$5="",$A10=""),"",IF(COUNTIFS('Leave Log'!$A$5:$A$304,$A10,'Leave Log'!$C$5:$C$304,"<="&H$5,'Leave Log'!$D$5:$D$304,">="&H$5,'Leave Log'!$F$5:$F$304,"<>Rejected",'Leave Log'!$B$5:$B$304,"AL")>0,"AL",IF(COUNTIFS('Leave Log'!$A$5:$A$304,$A10,'Leave Log'!$C$5:$C$304,"<="&H$5,'Leave Log'!$D$5:$D$304,">="&H$5,'Leave Log'!$F$5:$F$304,"<>Rejected",'Leave Log'!$B$5:$B$304,"SL")>0,"SL",IF(COUNTIFS('Leave Log'!$A$5:$A$304,$A10,'Leave Log'!$C$5:$C$304,"<="&H$5,'Leave Log'!$D$5:$D$304,">="&H$5,'Leave Log'!$F$5:$F$304,"<>Rejected",'Leave Log'!$B$5:$B$304,"CL")>0,"CL",IF(COUNTIFS('Leave Log'!$A$5:$A$304,$A10,'Leave Log'!$C$5:$C$304,"<="&H$5,'Leave Log'!$D$5:$D$304,">="&H$5,'Leave Log'!$F$5:$F$304,"<>Rejected",'Leave Log'!$B$5:$B$304,"UL")>0,"UL",IF(COUNTIFS('Leave Log'!$A$5:$A$304,$A10,'Leave Log'!$C$5:$C$304,"<="&H$5,'Leave Log'!$D$5:$D$304,">="&H$5,'Leave Log'!$F$5:$F$304,"<>Rejected",'Leave Log'!$B$5:$B$304,"OT")>0,"OT","")))))) | I10: =IF(OR(I$5="",$A10=""),"",IF(COUNTIFS('Leave Log'!$A$5:$A$304,$A10,'Leave Log'!$C$5:$C$304,"<="&I$5,'Leave Log'!$D$5:$D$304,">="&I$5,'Leave Log'!$F$5:$F$304,"<>Rejected",'Leave Log'!$B$5:$B$304,"AL")>0,"AL",IF(COUNTIFS('Leave Log'!$A$5:$A$304,$A10,'Leave Log'!$C$5:$C$304,"<="&I$5,'Leave Log'!$D$5:$D$304,">="&I$5,'Leave Log'!$F$5:$F$304,"<>Rejected",'Leave Log'!$B$5:$B$304,"SL")>0,"SL",IF(COUNTIFS('Leave Log'!$A$5:$A$304,$A10,'Leave Log'!$C$5:$C$304,"<="&I$5,'Leave Log'!$D$5:$D$304,">="&I$5,'Leave Log'!$F$5:$F$304,"<>Rejected",'Leave Log'!$B$5:$B$304,"CL")>0,"CL",IF(COUNTIFS('Leave Log'!$A$5:$A$304,$A10,'Leave Log'!$C$5:$C$304,"<="&I$5,'Leave Log'!$D$5:$D$304,">="&I$5,'Leave Log'!$F$5:$F$304,"<>Rejected",'Leave Log'!$B$5:$B$304,"UL")>0,"UL",IF(COUNTIFS('Leave Log'!$A$5:$A$304,$A10,'Leave Log'!$C$5:$C$304,"<="&I$5,'Leave Log'!$D$5:$D$304,">="&I$5,'Leave Log'!$F$5:$F$304,"<>Rejected",'Leave Log'!$B$5:$B$304,"OT")>0,"OT","")))))) | J10: =IF(OR(J$5="",$A10=""),"",IF(COUNTIFS('Leave Log'!$A$5:$A$304,$A10,'Leave Log'!$C$5:$C$304,"<="&J$5,'Leave Log'!$D$5:$D$304,">="&J$5,'Leave Log'!$F$5:$F$304,"<>Rejected",'Leave Log'!$B$5:$B$304,"AL")>0,"AL",IF(COUNTIFS('Leave Log'!$A$5:$A$304,$A10,'Leave Log'!$C$5:$C$304,"<="&J$5,'Leave Log'!$D$5:$D$304,">="&J$5,'Leave Log'!$F$5:$F$304,"<>Rejected",'Leave Log'!$B$5:$B$304,"SL")>0,"SL",IF(COUNTIFS('Leave Log'!$A$5:$A$304,$A10,'Leave Log'!$C$5:$C$304,"<="&J$5,'Leave Log'!$D$5:$D$304,">="&J$5,'Leave Log'!$F$5:$F$304,"<>Rejected",'Leave Log'!$B$5:$B$304,"CL")>0,"CL",IF(COUNTIFS('Leave Log'!$A$5:$A$304,$A10,'Leave Log'!$C$5:$C$304,"<="&J$5,'Leave Log'!$D$5:$D$304,">="&J$5,'Leave Log'!$F$5:$F$304,"<>Rejected",'Leave Log'!$B$5:$B$304,"UL")>0,"UL",IF(COUNTIFS('Leave Log'!$A$5:$A$304,$A10,'Leave Log'!$C$5:$C$304,"<="&J$5,'Leave Log'!$D$5:$D$304,">="&J$5,'Leave Log'!$F$5:$F$304,"<>Rejected",'Leave Log'!$B$5:$B$304,"OT")>0,"OT","")))))) | ... AG10: =IF(OR(AG$5="",$A10=""),"",IF(COUNTIFS('Leave Log'!$A$5:$A$304,$A10,'Leave Log'!$C$5:$C$304,"<="&AG$5,'Leave Log'!$D$5:$D$304,">="&AG$5,'Leave Log'!$F$5:$F$304,"<>Rejected",'Leave Log'!$B$5:$B$304,"AL")>0,"AL",IF(COUNTIFS('Leave Log'!$A$5:$A$304,$A10,'Leave Log'!$C$5:$C$304,"<="&AG$5,'Leave Log'!$D$5:$D$304,">="&AG$5,'Leave Log'!$F$5:$F$304,"<>Rejected",'Leave Log'!$B$5:$B$304,"SL")>0,"SL",IF(COUNTIFS('Leave Log'!$A$5:$A$304,$A10,'Leave Log'!$C$5:$C$304,"<="&AG$5,'Leave Log'!$D$5:$D$304,">="&AG$5,'Leave Log'!$F$5:$F$304,"<>Rejected",'Leave Log'!$B$5:$B$304,"CL")>0,"CL",IF(COUNTIFS('Leave Log'!$A$5:$A$304,$A10,'Leave Log'!$C$5:$C$304,"<="&AG$5,'Leave Log'!$D$5:$D$304,">="&AG$5,'Leave Log'!$F$5:$F$304,"<>Rejected",'Leave Log'!$B$5:$B$304,"UL")>0,"UL",IF(COUNTIFS('Leave Log'!$A$5:$A$304,$A10,'Leave Log'!$C$5:$C$304,"<="&AG$5,'Leave Log'!$D$5:$D$304,">="&AG$5,'Leave Log'!$F$5:$F$304,"<>Rejected",'Leave Log'!$B$5:$B$304,"OT")>0,"OT",""))))))
A11: =IF(Employees!B10="","",Employees!B10) -> Farid Khan | B11: =IF(Employees!B10="","",Employees!C10) -> IT | C11: =IF(OR(C$5="",$A11=""),"",IF(COUNTIFS('Leave Log'!$A$5:$A$304,$A11,'Leave Log'!$C$5:$C$304,"<="&C$5,'Leave Log'!$D$5:$D$304,">="&C$5,'Leave Log'!$F$5:$F$304,"<>Rejected",'Leave Log'!$B$5:$B$304,"AL")>0,"AL",IF(COUNTIFS('Leave Log'!$A$5:$A$304,$A11,'Leave Log'!$C$5:$C$304,"<="&C$5,'Leave Log'!$D$5:$D$304,">="&C$5,'Leave Log'!$F$5:$F$304,"<>Rejected",'Leave Log'!$B$5:$B$304,"SL")>0,"SL",IF(COUNTIFS('Leave Log'!$A$5:$A$304,$A11,'Leave Log'!$C$5:$C$304,"<="&C$5,'Leave Log'!$D$5:$D$304,">="&C$5,'Leave Log'!$F$5:$F$304,"<>Rejected",'Leave Log'!$B$5:$B$304,"CL")>0,"CL",IF(COUNTIFS('Leave Log'!$A$5:$A$304,$A11,'Leave Log'!$C$5:$C$304,"<="&C$5,'Leave Log'!$D$5:$D$304,">="&C$5,'Leave Log'!$F$5:$F$304,"<>Rejected",'Leave Log'!$B$5:$B$304,"UL")>0,"UL",IF(COUNTIFS('Leave Log'!$A$5:$A$304,$A11,'Leave Log'!$C$5:$C$304,"<="&C$5,'Leave Log'!$D$5:$D$304,">="&C$5,'Leave Log'!$F$5:$F$304,"<>Rejected",'Leave Log'!$B$5:$B$304,"OT")>0,"OT","")))))) | D11: =IF(OR(D$5="",$A11=""),"",IF(COUNTIFS('Leave Log'!$A$5:$A$304,$A11,'Leave Log'!$C$5:$C$304,"<="&D$5,'Leave Log'!$D$5:$D$304,">="&D$5,'Leave Log'!$F$5:$F$304,"<>Rejected",'Leave Log'!$B$5:$B$304,"AL")>0,"AL",IF(COUNTIFS('Leave Log'!$A$5:$A$304,$A11,'Leave Log'!$C$5:$C$304,"<="&D$5,'Leave Log'!$D$5:$D$304,">="&D$5,'Leave Log'!$F$5:$F$304,"<>Rejected",'Leave Log'!$B$5:$B$304,"SL")>0,"SL",IF(COUNTIFS('Leave Log'!$A$5:$A$304,$A11,'Leave Log'!$C$5:$C$304,"<="&D$5,'Leave Log'!$D$5:$D$304,">="&D$5,'Leave Log'!$F$5:$F$304,"<>Rejected",'Leave Log'!$B$5:$B$304,"CL")>0,"CL",IF(COUNTIFS('Leave Log'!$A$5:$A$304,$A11,'Leave Log'!$C$5:$C$304,"<="&D$5,'Leave Log'!$D$5:$D$304,">="&D$5,'Leave Log'!$F$5:$F$304,"<>Rejected",'Leave Log'!$B$5:$B$304,"UL")>0,"UL",IF(COUNTIFS('Leave Log'!$A$5:$A$304,$A11,'Leave Log'!$C$5:$C$304,"<="&D$5,'Leave Log'!$D$5:$D$304,">="&D$5,'Leave Log'!$F$5:$F$304,"<>Rejected",'Leave Log'!$B$5:$B$304,"OT")>0,"OT","")))))) | E11: =IF(OR(E$5="",$A11=""),"",IF(COUNTIFS('Leave Log'!$A$5:$A$304,$A11,'Leave Log'!$C$5:$C$304,"<="&E$5,'Leave Log'!$D$5:$D$304,">="&E$5,'Leave Log'!$F$5:$F$304,"<>Rejected",'Leave Log'!$B$5:$B$304,"AL")>0,"AL",IF(COUNTIFS('Leave Log'!$A$5:$A$304,$A11,'Leave Log'!$C$5:$C$304,"<="&E$5,'Leave Log'!$D$5:$D$304,">="&E$5,'Leave Log'!$F$5:$F$304,"<>Rejected",'Leave Log'!$B$5:$B$304,"SL")>0,"SL",IF(COUNTIFS('Leave Log'!$A$5:$A$304,$A11,'Leave Log'!$C$5:$C$304,"<="&E$5,'Leave Log'!$D$5:$D$304,">="&E$5,'Leave Log'!$F$5:$F$304,"<>Rejected",'Leave Log'!$B$5:$B$304,"CL")>0,"CL",IF(COUNTIFS('Leave Log'!$A$5:$A$304,$A11,'Leave Log'!$C$5:$C$304,"<="&E$5,'Leave Log'!$D$5:$D$304,">="&E$5,'Leave Log'!$F$5:$F$304,"<>Rejected",'Leave Log'!$B$5:$B$304,"UL")>0,"UL",IF(COUNTIFS('Leave Log'!$A$5:$A$304,$A11,'Leave Log'!$C$5:$C$304,"<="&E$5,'Leave Log'!$D$5:$D$304,">="&E$5,'Leave Log'!$F$5:$F$304,"<>Rejected",'Leave Log'!$B$5:$B$304,"OT")>0,"OT","")))))) | F11: =IF(OR(F$5="",$A11=""),"",IF(COUNTIFS('Leave Log'!$A$5:$A$304,$A11,'Leave Log'!$C$5:$C$304,"<="&F$5,'Leave Log'!$D$5:$D$304,">="&F$5,'Leave Log'!$F$5:$F$304,"<>Rejected",'Leave Log'!$B$5:$B$304,"AL")>0,"AL",IF(COUNTIFS('Leave Log'!$A$5:$A$304,$A11,'Leave Log'!$C$5:$C$304,"<="&F$5,'Leave Log'!$D$5:$D$304,">="&F$5,'Leave Log'!$F$5:$F$304,"<>Rejected",'Leave Log'!$B$5:$B$304,"SL")>0,"SL",IF(COUNTIFS('Leave Log'!$A$5:$A$304,$A11,'Leave Log'!$C$5:$C$304,"<="&F$5,'Leave Log'!$D$5:$D$304,">="&F$5,'Leave Log'!$F$5:$F$304,"<>Rejected",'Leave Log'!$B$5:$B$304,"CL")>0,"CL",IF(COUNTIFS('Leave Log'!$A$5:$A$304,$A11,'Leave Log'!$C$5:$C$304,"<="&F$5,'Leave Log'!$D$5:$D$304,">="&F$5,'Leave Log'!$F$5:$F$304,"<>Rejected",'Leave Log'!$B$5:$B$304,"UL")>0,"UL",IF(COUNTIFS('Leave Log'!$A$5:$A$304,$A11,'Leave Log'!$C$5:$C$304,"<="&F$5,'Leave Log'!$D$5:$D$304,">="&F$5,'Leave Log'!$F$5:$F$304,"<>Rejected",'Leave Log'!$B$5:$B$304,"OT")>0,"OT","")))))) | G11: =IF(OR(G$5="",$A11=""),"",IF(COUNTIFS('Leave Log'!$A$5:$A$304,$A11,'Leave Log'!$C$5:$C$304,"<="&G$5,'Leave Log'!$D$5:$D$304,">="&G$5,'Leave Log'!$F$5:$F$304,"<>Rejected",'Leave Log'!$B$5:$B$304,"AL")>0,"AL",IF(COUNTIFS('Leave Log'!$A$5:$A$304,$A11,'Leave Log'!$C$5:$C$304,"<="&G$5,'Leave Log'!$D$5:$D$304,">="&G$5,'Leave Log'!$F$5:$F$304,"<>Rejected",'Leave Log'!$B$5:$B$304,"SL")>0,"SL",IF(COUNTIFS('Leave Log'!$A$5:$A$304,$A11,'Leave Log'!$C$5:$C$304,"<="&G$5,'Leave Log'!$D$5:$D$304,">="&G$5,'Leave Log'!$F$5:$F$304,"<>Rejected",'Leave Log'!$B$5:$B$304,"CL")>0,"CL",IF(COUNTIFS('Leave Log'!$A$5:$A$304,$A11,'Leave Log'!$C$5:$C$304,"<="&G$5,'Leave Log'!$D$5:$D$304,">="&G$5,'Leave Log'!$F$5:$F$304,"<>Rejected",'Leave Log'!$B$5:$B$304,"UL")>0,"UL",IF(COUNTIFS('Leave Log'!$A$5:$A$304,$A11,'Leave Log'!$C$5:$C$304,"<="&G$5,'Leave Log'!$D$5:$D$304,">="&G$5,'Leave Log'!$F$5:$F$304,"<>Rejected",'Leave Log'!$B$5:$B$304,"OT")>0,"OT","")))))) | H11: =IF(OR(H$5="",$A11=""),"",IF(COUNTIFS('Leave Log'!$A$5:$A$304,$A11,'Leave Log'!$C$5:$C$304,"<="&H$5,'Leave Log'!$D$5:$D$304,">="&H$5,'Leave Log'!$F$5:$F$304,"<>Rejected",'Leave Log'!$B$5:$B$304,"AL")>0,"AL",IF(COUNTIFS('Leave Log'!$A$5:$A$304,$A11,'Leave Log'!$C$5:$C$304,"<="&H$5,'Leave Log'!$D$5:$D$304,">="&H$5,'Leave Log'!$F$5:$F$304,"<>Rejected",'Leave Log'!$B$5:$B$304,"SL")>0,"SL",IF(COUNTIFS('Leave Log'!$A$5:$A$304,$A11,'Leave Log'!$C$5:$C$304,"<="&H$5,'Leave Log'!$D$5:$D$304,">="&H$5,'Leave Log'!$F$5:$F$304,"<>Rejected",'Leave Log'!$B$5:$B$304,"CL")>0,"CL",IF(COUNTIFS('Leave Log'!$A$5:$A$304,$A11,'Leave Log'!$C$5:$C$304,"<="&H$5,'Leave Log'!$D$5:$D$304,">="&H$5,'Leave Log'!$F$5:$F$304,"<>Rejected",'Leave Log'!$B$5:$B$304,"UL")>0,"UL",IF(COUNTIFS('Leave Log'!$A$5:$A$304,$A11,'Leave Log'!$C$5:$C$304,"<="&H$5,'Leave Log'!$D$5:$D$304,">="&H$5,'Leave Log'!$F$5:$F$304,"<>Rejected",'Leave Log'!$B$5:$B$304,"OT")>0,"OT","")))))) | I11: =IF(OR(I$5="",$A11=""),"",IF(COUNTIFS('Leave Log'!$A$5:$A$304,$A11,'Leave Log'!$C$5:$C$304,"<="&I$5,'Leave Log'!$D$5:$D$304,">="&I$5,'Leave Log'!$F$5:$F$304,"<>Rejected",'Leave Log'!$B$5:$B$304,"AL")>0,"AL",IF(COUNTIFS('Leave Log'!$A$5:$A$304,$A11,'Leave Log'!$C$5:$C$304,"<="&I$5,'Leave Log'!$D$5:$D$304,">="&I$5,'Leave Log'!$F$5:$F$304,"<>Rejected",'Leave Log'!$B$5:$B$304,"SL")>0,"SL",IF(COUNTIFS('Leave Log'!$A$5:$A$304,$A11,'Leave Log'!$C$5:$C$304,"<="&I$5,'Leave Log'!$D$5:$D$304,">="&I$5,'Leave Log'!$F$5:$F$304,"<>Rejected",'Leave Log'!$B$5:$B$304,"CL")>0,"CL",IF(COUNTIFS('Leave Log'!$A$5:$A$304,$A11,'Leave Log'!$C$5:$C$304,"<="&I$5,'Leave Log'!$D$5:$D$304,">="&I$5,'Leave Log'!$F$5:$F$304,"<>Rejected",'Leave Log'!$B$5:$B$304,"UL")>0,"UL",IF(COUNTIFS('Leave Log'!$A$5:$A$304,$A11,'Leave Log'!$C$5:$C$304,"<="&I$5,'Leave Log'!$D$5:$D$304,">="&I$5,'Leave Log'!$F$5:$F$304,"<>Rejected",'Leave Log'!$B$5:$B$304,"OT")>0,"OT","")))))) | J11: =IF(OR(J$5="",$A11=""),"",IF(COUNTIFS('Leave Log'!$A$5:$A$304,$A11,'Leave Log'!$C$5:$C$304,"<="&J$5,'Leave Log'!$D$5:$D$304,">="&J$5,'Leave Log'!$F$5:$F$304,"<>Rejected",'Leave Log'!$B$5:$B$304,"AL")>0,"AL",IF(COUNTIFS('Leave Log'!$A$5:$A$304,$A11,'Leave Log'!$C$5:$C$304,"<="&J$5,'Leave Log'!$D$5:$D$304,">="&J$5,'Leave Log'!$F$5:$F$304,"<>Rejected",'Leave Log'!$B$5:$B$304,"SL")>0,"SL",IF(COUNTIFS('Leave Log'!$A$5:$A$304,$A11,'Leave Log'!$C$5:$C$304,"<="&J$5,'Leave Log'!$D$5:$D$304,">="&J$5,'Leave Log'!$F$5:$F$304,"<>Rejected",'Leave Log'!$B$5:$B$304,"CL")>0,"CL",IF(COUNTIFS('Leave Log'!$A$5:$A$304,$A11,'Leave Log'!$C$5:$C$304,"<="&J$5,'Leave Log'!$D$5:$D$304,">="&J$5,'Leave Log'!$F$5:$F$304,"<>Rejected",'Leave Log'!$B$5:$B$304,"UL")>0,"UL",IF(COUNTIFS('Leave Log'!$A$5:$A$304,$A11,'Leave Log'!$C$5:$C$304,"<="&J$5,'Leave Log'!$D$5:$D$304,">="&J$5,'Leave Log'!$F$5:$F$304,"<>Rejected",'Leave Log'!$B$5:$B$304,"OT")>0,"OT","")))))) | ... AG11: =IF(OR(AG$5="",$A11=""),"",IF(COUNTIFS('Leave Log'!$A$5:$A$304,$A11,'Leave Log'!$C$5:$C$304,"<="&AG$5,'Leave Log'!$D$5:$D$304,">="&AG$5,'Leave Log'!$F$5:$F$304,"<>Rejected",'Leave Log'!$B$5:$B$304,"AL")>0,"AL",IF(COUNTIFS('Leave Log'!$A$5:$A$304,$A11,'Leave Log'!$C$5:$C$304,"<="&AG$5,'Leave Log'!$D$5:$D$304,">="&AG$5,'Leave Log'!$F$5:$F$304,"<>Rejected",'Leave Log'!$B$5:$B$304,"SL")>0,"SL",IF(COUNTIFS('Leave Log'!$A$5:$A$304,$A11,'Leave Log'!$C$5:$C$304,"<="&AG$5,'Leave Log'!$D$5:$D$304,">="&AG$5,'Leave Log'!$F$5:$F$304,"<>Rejected",'Leave Log'!$B$5:$B$304,"CL")>0,"CL",IF(COUNTIFS('Leave Log'!$A$5:$A$304,$A11,'Leave Log'!$C$5:$C$304,"<="&AG$5,'Leave Log'!$D$5:$D$304,">="&AG$5,'Leave Log'!$F$5:$F$304,"<>Rejected",'Leave Log'!$B$5:$B$304,"UL")>0,"UL",IF(COUNTIFS('Leave Log'!$A$5:$A$304,$A11,'Leave Log'!$C$5:$C$304,"<="&AG$5,'Leave Log'!$D$5:$D$304,">="&AG$5,'Leave Log'!$F$5:$F$304,"<>Rejected",'Leave Log'!$B$5:$B$304,"OT")>0,"OT",""))))))
